Workbook

Sheet MS- 0028921 Limpeza
C2: Formulário de Registro para Ensaio Inspeção Passa/Falha
B5: Ordem de Serviço - OS | C5: BR26NODK 001
B6: Técnico responsável: | C6: João e Raissa
B7: Norma e Item da norma: | C7: ABNT NBR ISO 7864:2020 - Item 4.3 Limpeza
B8: Fabricante: | C8: Terumo Europe - Bélgica.
B9: Produto: | C9: Agulha hipodérmica estéril para uso único
B10: Modelo: | C10: Agulha Hipodérmica LL e LS (K-Pack) 0,40 x 12 mm 27G X 1/2 - Cod: KH-2713RBBTUCI - Lote: 2509064, (TÜV 25.1393)
B11: Observações:
B12: Informações adicionais do ensaio
B13: Equipamentos utilizados: | C13: Luximetro TUV-LAB-0941, Termohigrômetro TUV-LAB-1116.
B14: Data de execução do ensaio: | C14: 46445
B15: Condições Ambientais | C15: Temperatura (°C): 22 | D15: Umidade (%): 74
B18: Atende o requisito ? | C18: Observações
A19: 1
A20: 2
A21: 3
A22: 4
A23: 5
A24: 6
A25: 7
A26: 8
A27: 9
A28: 10
A29: 11
A30: 12
... A50: 32
B52: Conferido por: João J. da Silva.

Sheet MS- 0028921 PH 
C3: Formulário de Registro para PH
B6: Ordem de Serviço - OS | C6: BR26NODK 001
B7: Técnico responsável: | C7: João / Raissa
B8: Norma e Item da norma: | C8: ABNT NBR ISO 7864:2020 - Item 4.4 Limites de acidez ou alcalinidade
B9: Fabricante: | C9: Terumo Europe - Bélgica.
B10: Produto: | C10: ='MS- 0028921 Limpeza'!C9 -> Agulha hipodérmica estéril para uso único
B11: Modelo: | C11: Agulha Hipodérmica LL e LS (K-Pack) 0,40 x 12 mm 27G X 1/2 - Cod: KH-2713RBBTUCI - Lote: 2509064, (TÜV 25.1393)
B12: Observações:
B13: Informações adicionais do ensaio
B14: Equipamentos utilizados: | C14: pHmetro TUV-LAB-1518, Estufa TUV-LAB-0918, Cronômetro 9018144, Termohigrômetro TUV-LAB-1520.
B15: Data de execução do ensaio: | C15: 46086
B16: Condições Ambientais | C16: Temperatura (°C): 21 | D16: Umidade (%): 74
B17: Tempo de preparação de amostra | C17: Início: 10h | D17: Término: 11h
B18: Produto químicos | D18: Números: 1352,1353 e 1499
B22: Valor do pH do | C22: Tolerância | D22: Tolerância
B23: Fluído de controle | C23: Valor Máximo Especificado | D23: Valor Mínimo Especificado
B24: 6.7 | C24: 1 | D24: 1
C25: =IF(B24="","-",B24+C24) -> 7.7 | D25: =IF(B24="","-",B24-D24) -> 5.7
B28: Valor do PH | C28: Verificação
A29: 1 | B29: 6.72 | C29: =IF(B29="","",IF(B29>=$D$25,IF(B29<$C$25,"Aprovado","Reprovado"),"Reprovado")) -> Aprovado
A30: 2 | B30: 6.56 | C30: =IF(B30="","",IF(B30>=$D$25,IF(B30<$C$25,"Aprovado","Reprovado"),"Reprovado")) -> Aprovado
A31: 3 | B31: 6.39 | C31: =IF(B31="","",IF(B31>=$D$25,IF(B31<$C$25,"Aprovado","Reprovado"),"Reprovado")) -> Aprovado
A32: 4 | B32: 6.17 | C32: =IF(B32="","",IF(B32>=$D$25,IF(B32<$C$25,"Aprovado","Reprovado"),"Reprovado")) -> Aprovado
A33: 5 | B33: 6.21 | C33: =IF(B33="","",IF(B33>=$D$25,IF(B33<$C$25,"Aprovado","Reprovado"),"Reprovado")) -> Aprovado
A34: 6 | B34: 6.67 | C34: =IF(B34="","",IF(B34>=$D$25,IF(B34<$C$25,"Aprovado","Reprovado"),"Reprovado")) -> Aprovado
A35: 7 | B35: 6.65 | C35: =IF(B35="","",IF(B35>=$D$25,IF(B35<$C$25,"Aprovado","Reprovado"),"Reprovado")) -> Aprovado
A36: 8 | B36: 6.24 | C36: =IF(B36="","",IF(B36>=$D$25,IF(B36<$C$25,"Aprovado","Reprovado"),"Reprovado")) -> Aprovado
A37: 9 | B37: 6.58 | C37: =IF(B37="","",IF(B37>=$D$25,IF(B37<$C$25,"Aprovado","Reprovado"),"Reprovado")) -> Aprovado
A38: 10 | B38: 6.55 | C38: =IF(B38="","",IF(B38>=$D$25,IF(B38<$C$25,"Aprovado","Reprovado"),"Reprovado")) -> Aprovado
A39: 11 | B39: 6.57 | C39: =IF(B39="","",IF(B39>=$D$25,IF(B39<$C$25,"Aprovado","Reprovado"),"Reprovado")) -> Aprovado
A40: 12 | B40: 6.62 | C40: =IF(B40="","",IF(B40>=$D$25,IF(B40<$C$25,"Aprovado","Reprovado"),"Reprovado")) -> Aprovado
... A60: 32 | B60: 6.65 | C60: =IF(B60="","",IF(B60>=$D$25,IF(B60<$C$25,"Aprovado","Reprovado"),"Reprovado")) -> Aprovado
B62: Conferido por: João J. da Silva.

Sheet MS- 0028921 Metais extraíveis
C2: Formulário de Registro de Metais Extraíveis
B5: Ordem de Serviço - OS | C5: BR26NODK 001
B6: Técnico responsável: | C6: João / Raissa
B7: Norma e Item da norma: | C7: ABNT NBR ISO 7864:2020 - Item 4.5 Limites para metais extraíveis
B8: Fabricante: | C8: Terumo Europe - Bélgica.
B9: Produto: | C9: ='MS- 0028921 Limpeza'!C9 -> Agulha hipodérmica estéril para uso único
B10: Modelo: | C10: Agulha Hipodérmica LL e LS (K-Pack) 0,40 x 12 mm 27G X 1/2 - Cod: KH-2713RBBTUCI - Lote: 2509064, (TÜV 25.1393)
B11: Observações:
B12: Informações adicionais do ensaio
B13: Equipamentos utilizados: | C13: Espectrofotômetro TUV-LAB-1132, Estufa TUV-LAB-918, Termohigrômetro TUV-LAB-1520, Cronômetro 9018144,TUV-LAB-1116.
B14: Data de execução do ensaio: | C14: 46086
B15: Condições Ambientais | C15: Temperatura (°C): 21 | D15: Umidade (%): 72
B16: Tempo de preparação de amostra | C16: Início: 10h | D16: Término: 11h
B17: Produto químicos | D17: Números: 758,760,762,764 e 770
B20: Agulha e Seringas
B21: Chumbo (mg/L) | C21: Estanho (mg/L) | D21: Zinco (mg/L) | E21: Ferro (mg/L) | F21: Somatório (mg/L) | G21: Cádmio (mg/L)
A22: 1 | B22: < L.Q. | C22: < L.Q. | D22: < L.Q. | E22: < L.Q. | F22: < 5 | G22: < L.Q.
A23: 2 | B23: < L.Q. | C23: < L.Q. | D23: < L.Q. | E23: < L.Q. | F23: < 5 | G23: < L.Q.
A24: 3 | B24: < L.Q. | C24: < L.Q. | D24: < L.Q. | E24: < L.Q. | F24: < 5 | G24: < L.Q.
A25: 4 | B25: < L.Q. | C25: < L.Q. | D25: < L.Q. | E25: < L.Q. | F25: < 5 | G25: < L.Q.
A26: 5 | B26: < L.Q. | C26: < L.Q. | D26: < L.Q. | E26: < L.Q. | F26: < 5 | G26: < L.Q.
A27: 6 | B27: < L.Q. | C27: < L.Q. | D27: < L.Q. | E27: < L.Q. | F27: < 5 | G27: < L.Q.
A28: 7 | B28: < L.Q. | C28: < L.Q. | D28: < L.Q. | E28: < L.Q. | F28: < 5 | G28: < L.Q.
A29: 8 | B29: < L.Q. | C29: < L.Q. | D29: < L.Q. | E29: < L.Q. | F29: < 5 | G29: < L.Q.
A30: 9 | B30: < L.Q. | C30: < L.Q. | D30: < L.Q. | E30: < L.Q. | F30: < 5 | G30: < L.Q.
A31: 10 | B31: < L.Q. | C31: < L.Q. | D31: < L.Q. | E31: < L.Q. | F31: < 5 | G31: < L.Q.
A32: 11 | B32: < L.Q. | C32: < L.Q. | D32: < L.Q. | E32: < L.Q. | F32: < 5 | G32: < L.Q.
A33: 12 | B33: < L.Q. | C33: < L.Q. | D33: < L.Q. | E33: < L.Q. | F33: < 5 | G33: < L.Q.
... A53: 32 | B53: < L.Q. | C53: < L.Q. | D53: < L.Q. | E53: < L.Q. | F53: < 5 | G53: < L.Q.
B55: Conferido por: João J. da Silva.
B57: Equipos
B58: Bário (mg/L) | C58: Cromo (mg/L) | D58: Cobre (mg/L) | E58: Chumbo (mg/L) | F58: Estanho (mg/L) | G58: Somatório (mg/L) | H58: Cádmio (mg/L)
A59: 1 | G59: =IF(B59="","",(B59+C59+D59+E59+F59))
A60: 2 | G60: =IF(B60="","",(B60+C60+D60+E60+F60))
A61: 3 | G61: =IF(B61="","",(B61+C61+D61+E61+F61))
A62: 4 | G62: =IF(B62="","",(B62+C62+D62+E62+F62))
A63: 5 | G63: =IF(B63="","",(B63+C63+D63+E63+F63))
A64: 6 | G64: =IF(B64="","",(B64+C64+D64+E64+F64))
A65: 7 | G65: =IF(B65="","",(B65+C65+D65+E65+F65))
A66: 8 | G66: =IF(B66="","",(B66+C66+D66+E66+F66))
...

Sheet MS-0028930 ISO 80369-7 e 20
B5: Ordem de Serviço - OS | D5: BR26NODK 001
B6: Técnico responsável: | D6: João / Raissa
B7: Norma e Item da norma: | D7: ABNT NBR ISO 7864:2020 - Item 4.8.1 Encaixe cônico da norma ABNT NBR ISO 80369-7:2022 e ABNT NBR ISO 80369-20:2021
B8: Fabricante: | D8: Terumo Europe - Bélgica.
B9: Produto: | D9: ='MS- 0028921 Limpeza'!C9 -> Agulha hipodérmica estéril para uso único | F9: Equipo de Infusão
B10: Modelo: | D10: Agulha Hipodérmica LL e LS (K-Pack) 0,40 x 12 mm 27G X 1/2 - Cod: KH-2713RBBTUCI - Lote: 2509064, (TÜV 25.1393)
B11: Observações: | D11: O item 6.1.1 diz que o ensaio de vaz liq. pode ser feito pelo método do item 6.1.2 ou 6.1.3, fiz pelo 6.1.3. - ( Item 6.5 e 6.6 Não aplicavel p bico Slip.)
B12: Informações adicionais de ensaio
B13: Equipamentos utilizados: | D13: Manômetro TUV-LAB-1471, Cronômetro 9018144, Dinamômetro TUV-LAB-1112, TUV-LAB-1116, TUV-LAB-1135-5 e Calibres Ruptura 9023875, Dispositivo de força e torque TUV-LAB-0988, Dsipositivo de apoio MES-049 e TUV-LAB-1469.
B15: Data de execução do ensaio: | D15: 02/03/2026 a
B16: Condições Ambientais | D16: Temperatura (°C): 22 | F16: Umidade (%): 65
B18: 6.1.1. - Vazamento de líquido Atende ao requisito? | C18: 6.1.2. - Vazamento por decaimento de pressão Atende ao requisito? | D18: 6.1.3. - Vazamento de liquido por pressão positiva Atende ao requisito? | E18: 6.2. - Vazamento de ar por pressão sub atmosférica Atende ao requisito? | F18: 6.3. - Esforço de ruptura Atende ao requisito? | G18: 6.4. - Resistência de separação de carga axial Atende ao requisito? | H18: 6.5. - Resistencia de separação por desatarraxo Atende ao requisito? | I18: 6.6. - Resistência à fadiga Atende ao requisito?
A19: 1
A20: 2 | K20: 14 a 17/03/2025 - 6.3 - Ruptura 48h
A21: 3 | K21: 19/03/2025 - 6.1.1 e 6.1.3 -Vazamentos
A22: 4 | K22: 19/03 - 6.2 - Vazamento sub
A23: 5 | K23: 18/03- 6.4 - R. Separação
A24: 6
A25: 7
A26: 8
A27: 9
A28: 10
A29: 11
A30: 12
A31: 13
A32: 14
A33: 15
A34: 16
A35: 17
... A50: 32
B52: Conferido por: João J. da Silva.

Sheet MS-0028930 ISO 80369-20
C2: Formulário de Registro para Vazamento de ar pressã
B5: Ordem de Serviço - OS | C5: BR26NODK 001
B6: Técnico responsável: | C6: João / Raissa
B7: Norma e Item da norma: | C7: ABNT NBR ISO 80369-7 e 20 - 6.2 Vazamento de ar por pressão sub-atmosféria
B8: Fabricante: | C8: Terumo Europe - Bélgica.
B9: Produto: | C9: ='MS- 0028921 Limpeza'!C9 -> Agulha hipodérmica estéril para uso único
B10: Modelo: | C10: Agulha Hipodérmica LL e LS (K-Pack) 0,40 x 12 mm 27G X 1/2 - Cod: KH-2713RBBTUCI - Lote: 2509064, (TÜV 25.1393)
B11: Observações: | C11: O ensaio foi realizado na condição Luer Slip.
B12: Informações adicionais do ensaio
B13: Equipamentos utilizados: | C13: Termohigrômetro TUV-LAB 1116, Cronômetro TUV-LAB 9018144, Dispositivo de força e torque TUV-LAV 0988, Calibres TUV-LAB-1135-5, Monovacuômetro TUV LAB 0950.
B14: Data de execução do ensaio: | C14: 09/03/2026 a 10/03/2026
B15: Condições Ambientais | C15: Temperatura(ºC): 23 | D15: Umidade(%): 77
B18: Volume mL | C18: 6.22 | E18: Limite Pa.m3/s | F18: 0.005
B19: Sp- Pressão min (KPa) | C19: -85
B20: tp - Pressão inicial do teste (KPa) | C20: Pressão final do teste ( kPa) | D20: Δp (Variação de pressão) Pa | E20: Δt Tempo do ensaio (s) | F20: L = Taxa de vazamento (Pa.m3/s) | G20: Veridito
A21: 1 | B21: -85,0 | C21: -85.1 | D21: =IF(B21="","",ABS((C21-B21)*1000)) -> 100 | E21: 20 | F21: =IF(B21="","",ABS(($C$19/B21))*($C$18*0.000001)*(D21/E21)) -> 3.11e-05 | G21: C
A22: 2 | B22: -85,0 | C22: -85 | D22: =IF(B22="","",ABS((C22-B22)*1000)) -> 0 | E22: 20 | F22: =IF(B22="","",ABS(($C$19/B22))*($C$18*0.000001)*(D22/E22)) -> 0 | G22: C
A23: 3 | B23: -85,0 | C23: -85.1 | D23: =IF(B23="","",ABS((C23-B23)*1000)) -> 100 | E23: 20 | F23: =IF(B23="","",ABS(($C$19/B23))*($C$18*0.000001)*(D23/E23)) -> 3.11e-05 | G23: C
A24: 4 | B24: -85,0 | C24: -85 | D24: =IF(B24="","",ABS((C24-B24)*1000)) -> 0 | E24: 20 | F24: =IF(B24="","",ABS(($C$19/B24))*($C$18*0.000001)*(D24/E24)) -> 0 | G24: C
A25: 5 | B25: -85,0 | C25: -85 | D25: =IF(B25="","",ABS((C25-B25)*1000)) -> 0 | E25: 20 | F25: =IF(B25="","",ABS(($C$19/B25))*($C$18*0.000001)*(D25/E25)) -> 0 | G25: C
A26: 6 | B26: -85,0 | C26: -85.1 | D26: =IF(B26="","",ABS((C26-B26)*1000)) -> 100 | E26: 20 | F26: =IF(B26="","",ABS(($C$19/B26))*($C$18*0.000001)*(D26/E26)) -> 3.11e-05 | G26: C
A27: 7 | B27: -85,0 | C27: -85.2 | D27: =IF(B27="","",ABS((C27-B27)*1000)) -> 200 | E27: 20 | F27: =IF(B27="","",ABS(($C$19/B27))*($C$18*0.000001)*(D27/E27)) -> 6.22e-05 | G27: C
A28: 8 | B28: -85,0 | C28: -85 | D28: =IF(B28="","",ABS((C28-B28)*1000)) -> 0 | E28: 20 | F28: =IF(B28="","",ABS(($C$19/B28))*($C$18*0.000001)*(D28/E28)) -> 0 | G28: C
A29: 9 | B29: -85,0 | C29: -85 | D29: =IF(B29="","",ABS((C29-B29)*1000)) -> 0 | E29: 20 | F29: =IF(B29="","",ABS(($C$19/B29))*($C$18*0.000001)*(D29/E29)) -> 0 | G29: C
A30: 10 | B30: -85,0 | C30: -85 | D30: =IF(B30="","",ABS((C30-B30)*1000)) -> 0 | E30: 20 | F30: =IF(B30="","",ABS(($C$19/B30))*($C$18*0.000001)*(D30/E30)) -> 0 | G30: C
A31: 11 | B31: -85,0 | C31: -85 | D31: =IF(B31="","",ABS((C31-B31)*1000)) -> 0 | E31: 20 | F31: =IF(B31="","",ABS(($C$19/B31))*($C$18*0.000001)*(D31/E31)) -> 0 | G31: C
A32: 12 | B32: -85,0 | C32: -85.1 | D32: =IF(B32="","",ABS((C32-B32)*1000)) -> 100 | E32: 20 | F32: =IF(B32="","",ABS(($C$19/B32))*($C$18*0.000001)*(D32/E32)) -> 3.11e-05 | G32: C
... A52: 32 | B52: -85,0 | C52: -85 | D52: =IF(B52="","",ABS((C52-B52)*1000)) -> 0 | E52: 20 | F52: =IF(B52="","",ABS(($C$19/B52))*($C$18*0.000001)*(D52/E52)) -> 0 | G52: C
B53: Conferido por: João J. da Silva.
B59: Anexo 1 - MS-0028930_Rev.03 - 6.2 Vazamento de ar por pressão sub-atmosféria da ABNT NBR ISO 80369-7 e 20.

Sheet Planilha1

Sheet Planilha2

Sheet MS-0028930 ISO 80369-20 (2)
C2: Formulário de Registro para Vazamento de ar pressã
B5: Ordem de Serviço - OS | C5: BR26NODK 001
B6: Técnico responsável: | C6: João / Raissa
B7: Norma e Item da norma: | C7: ABNT NBR ISO 80369-7 e 20 - 6.2 Vazamento de ar por pressão sub-atmosféria
B8: Fabricante: | C8: Terumo Europe - Bélgica.
B9: Produto: | C9: ='MS- 0028921 Limpeza'!C9 -> Agulha hipodérmica estéril para uso único
B10: Modelo: | C10: Agulha Hipodérmica LL e LS (K-Pack) 0,40 x 12 mm 27G X 1/2 - Cod: KH-2713RBBTUCI - Lote: 2509064, (TÜV 25.1393)
B11: Observações: | C11: O ensaio foi realizado na condição Luer Lock.
B12: Informações adicionais do ensaio
B13: Equipamentos utilizados: | C13: Termohigrômetro TUV-LAB 1116, Cronômetro TUV-LAB 9018144, Dispositivo de força e torque TUV-LAV 0988, Calibres TUV-LAB-1135-5, Monovacuômetro TUV LAB 0950.
B14: Data de execução do ensaio: | C14: 46091
B15: Condições Ambientais | C15: Temperatura(ºC): 22 | D15: Umidade(%): 71
B18: Volume mL | C18: 6.22 | E18: Limite Pa.m3/s | F18: 0.005
B19: Sp- Pressão min (KPa) | C19: -85
B20: tp - Pressão inicial do teste (KPa) | C20: Pressão final do teste ( kPa) | D20: Δp (Variação de pressão) Pa | E20: Δt Tempo do ensaio (s) | F20: L = Taxa de vazamento (Pa.m3/s) | G20: Veridito
A21: 1 | B21: -85 | C21: -85 | D21: =IF(B21="","",ABS((C21-B21)*1000)) -> 0 | E21: 20 | F21: =IF(B21="","",ABS(($C$19/B21))*($C$18*0.000001)*(D21/E21)) -> 0 | G21: =IF(F21="","",IF(F21<=$F$18,"Conforme","Não Conforme")) -> Conforme
A22: 2 | B22: -85 | C22: -85 | D22: =IF(B22="","",ABS((C22-B22)*1000)) -> 0 | E22: 20 | F22: =IF(B22="","",ABS(($C$19/B22))*($C$18*0.000001)*(D22/E22)) -> 0 | G22: =IF(F22="","",IF(F22<=$F$18,"Conforme","Não Conforme")) -> Conforme
A23: 3 | B23: -85 | C23: -85.1 | D23: =IF(B23="","",ABS((C23-B23)*1000)) -> 100 | E23: 20 | F23: =IF(B23="","",ABS(($C$19/B23))*($C$18*0.000001)*(D23/E23)) -> 3.11e-05 | G23: =IF(F23="","",IF(F23<=$F$18,"Conforme","Não Conforme")) -> Conforme
A24: 4 | B24: -85 | C24: -85 | D24: =IF(B24="","",ABS((C24-B24)*1000)) -> 0 | E24: 20 | F24: =IF(B24="","",ABS(($C$19/B24))*($C$18*0.000001)*(D24/E24)) -> 0 | G24: =IF(F24="","",IF(F24<=$F$18,"Conforme","Não Conforme")) -> Conforme
A25: 5 | B25: -85 | C25: -85 | D25: =IF(B25="","",ABS((C25-B25)*1000)) -> 0 | E25: 20 | F25: =IF(B25="","",ABS(($C$19/B25))*($C$18*0.000001)*(D25/E25)) -> 0 | G25: =IF(F25="","",IF(F25<=$F$18,"Conforme","Não Conforme")) -> Conforme
A26: 6 | B26: -85 | C26: -85 | D26: =IF(B26="","",ABS((C26-B26)*1000)) -> 0 | E26: 20 | F26: =IF(B26="","",ABS(($C$19/B26))*($C$18*0.000001)*(D26/E26)) -> 0 | G26: =IF(F26="","",IF(F26<=$F$18,"Conforme","Não Conforme")) -> Conforme
A27: 7 | B27: -85 | C27: -85 | D27: =IF(B27="","",ABS((C27-B27)*1000)) -> 0 | E27: 20 | F27: =IF(B27="","",ABS(($C$19/B27))*($C$18*0.000001)*(D27/E27)) -> 0 | G27: =IF(F27="","",IF(F27<=$F$18,"Conforme","Não Conforme")) -> Conforme
A28: 8 | B28: -85 | C28: -85.1 | D28: =IF(B28="","",ABS((C28-B28)*1000)) -> 100 | E28: 20 | F28: =IF(B28="","",ABS(($C$19/B28))*($C$18*0.000001)*(D28/E28)) -> 3.11e-05 | G28: =IF(F28="","",IF(F28<=$F$18,"Conforme","Não Conforme")) -> Conforme
A29: 9 | B29: -85 | C29: -85 | D29: =IF(B29="","",ABS((C29-B29)*1000)) -> 0 | E29: 20 | F29: =IF(B29="","",ABS(($C$19/B29))*($C$18*0.000001)*(D29/E29)) -> 0 | G29: =IF(F29="","",IF(F29<=$F$18,"Conforme","Não Conforme")) -> Conforme
A30: 10 | B30: -85 | C30: -85 | D30: =IF(B30="","",ABS((C30-B30)*1000)) -> 0 | E30: 20 | F30: =IF(B30="","",ABS(($C$19/B30))*($C$18*0.000001)*(D30/E30)) -> 0 | G30: =IF(F30="","",IF(F30<=$F$18,"Conforme","Não Conforme")) -> Conforme
A31: 11 | B31: -85 | C31: -85 | D31: =IF(B31="","",ABS((C31-B31)*1000)) -> 0 | E31: 20 | F31: =IF(B31="","",ABS(($C$19/B31))*($C$18*0.000001)*(D31/E31)) -> 0 | G31: =IF(F31="","",IF(F31<=$F$18,"Conforme","Não Conforme")) -> Conforme
A32: 12 | B32: -85 | C32: -85 | D32: =IF(B32="","",ABS((C32-B32)*1000)) -> 0 | E32: 20 | F32: =IF(B32="","",ABS(($C$19/B32))*($C$18*0.000001)*(D32/E32)) -> 0 | G32: =IF(F32="","",IF(F32<=$F$18,"Conforme","Não Conforme")) -> Conforme
... A52: 32 | B52: -85 | C52: -85.1 | D52: =IF(B52="","",ABS((C52-B52)*1000)) -> 100 | E52: 20 | F52: =IF(B52="","",ABS(($C$19/B52))*($C$18*0.000001)*(D52/E52)) -> 3.11e-05 | G52: =IF(F52="","",IF(F52<=$F$18,"Conforme","Não Conforme")) -> Conforme
B53: Conferido por: João J. da Silva.
B59: Anexo 1 - MS-0028930_Rev.03 - 6.2 Vazamento de ar por pressão sub-atmosféria da ABNT NBR ISO 80369-7 e 20.

Sheet MS-0028921 Dimensões ISO962 
C2: Formulário de Registro para Diâmetro externo da Agulha - Cânula 9626
B5: Ordem de Serviço - OS | C5: BR26NODK 001
B6: Técnico responsável: | C6: João / Raissa
B7: Norma e Item da norma: | C7: ABNT NBR ISO 9626:2020 - Item 5.6 Dimensões (Diâmetro Externo e Interno)
B8: Fabricante: | C8: Terumo Europe - Bélgica.
B9: Produto: | C9: ='MS- 0028921 Limpeza'!C9 -> Agulha hipodérmica estéril para uso único
B10: Modelo: | C10: Agulha Hipodérmica LL e LS (K-Pack) 0,40 x 12 mm 27G X 1/2 - Cod: KH-2713RBBTUCI - Lote: 2509064, (TÜV 25.1393)
B11: Observações:
B12: Informações adicionais do ensaio
B13: Equipamentos utilizados: | C13: Micrômetro TUV-LAB-0902 , Projetor de Perfil UCMEL-031, Termohigrômetro 9058343 e Termohigrômetro TUV-LAB-1116.
B14: Data de execução do ensaio: | C14: 04/03/2026 a 09/03/2026
B15: Condições Ambientais | C15: Temperatura (°C): 22 | D15: Umidade (%): 64
B19: Diâmetro Externo Nominal (mm) | C19: Tolerância - Valor Mínimo Especificado (mm) | D19: Tolerância - Valor Máximo Especificado (mm) | E19: Diâmetro interno mínimo (mm) | F19: Tipo de parede
B20: 0.4 | C20: 0.4 | D20: 0.42 | E20: 0.241 | F20: fina
B23: Diâmetro externo Medido (mm) | C23: Verificação | D23: Diâmetro interno Medido (mm) | E23: Verificação
A24: 1 | B24: 0.413 | C24: =IF(B24="","",IF(B24<=$D$20,IF(B24>=$C$20,"Aprovado","Reprovado"),"Reprovado")) -> Aprovado | D24: 0.25 | E24: =IF(D24="","",IF(D24>=$E$20,"Aprovado","Reprovado")) -> Aprovado
A25: 2 | B25: 0.41 | C25: =IF(B25="","",IF(B25<=$D$20,IF(B25>=$C$20,"Aprovado","Reprovado"),"Reprovado")) -> Aprovado | D25: 0.252 | E25: =IF(D25="","",IF(D25>=$E$20,"Aprovado","Reprovado")) -> Aprovado
A26: 3 | B26: 0.415 | C26: =IF(B26="","",IF(B26<=$D$20,IF(B26>=$C$20,"Aprovado","Reprovado"),"Reprovado")) -> Aprovado | D26: 0.256 | E26: =IF(D26="","",IF(D26>=$E$20,"Aprovado","Reprovado")) -> Aprovado
A27: 4 | B27: 0.415 | C27: =IF(B27="","",IF(B27<=$D$20,IF(B27>=$C$20,"Aprovado","Reprovado"),"Reprovado")) -> Aprovado | D27: 0.262 | E27: =IF(D27="","",IF(D27>=$E$20,"Aprovado","Reprovado")) -> Aprovado
A28: 5 | B28: 0.416 | C28: =IF(B28="","",IF(B28<=$D$20,IF(B28>=$C$20,"Aprovado","Reprovado"),"Reprovado")) -> Aprovado | D28: 0.261 | E28: =IF(D28="","",IF(D28>=$E$20,"Aprovado","Reprovado")) -> Aprovado
A29: 6 | B29: 0.416 | C29: =IF(B29="","",IF(B29<=$D$20,IF(B29>=$C$20,"Aprovado","Reprovado"),"Reprovado")) -> Aprovado | D29: 0.262 | E29: =IF(D29="","",IF(D29>=$E$20,"Aprovado","Reprovado")) -> Aprovado
A30: 7 | B30: 0.416 | C30: =IF(B30="","",IF(B30<=$D$20,IF(B30>=$C$20,"Aprovado","Reprovado"),"Reprovado")) -> Aprovado | D30: 0.251 | E30: =IF(D30="","",IF(D30>=$E$20,"Aprovado","Reprovado")) -> Aprovado
A31: 8 | B31: 0.415 | C31: =IF(B31="","",IF(B31<=$D$20,IF(B31>=$C$20,"Aprovado","Reprovado"),"Reprovado")) -> Aprovado | D31: 0.253 | E31: =IF(D31="","",IF(D31>=$E$20,"Aprovado","Reprovado")) -> Aprovado
A32: 9 | B32: 0.41 | C32: =IF(B32="","",IF(B32<=$D$20,IF(B32>=$C$20,"Aprovado","Reprovado"),"Reprovado")) -> Aprovado | D32: 0.255 | E32: =IF(D32="","",IF(D32>=$E$20,"Aprovado","Reprovado")) -> Aprovado
A33: 10 | B33: 0.41 | C33: =IF(B33="","",IF(B33<=$D$20,IF(B33>=$C$20,"Aprovado","Reprovado"),"Reprovado")) -> Aprovado | D33: 0.253 | E33: =IF(D33="","",IF(D33>=$E$20,"Aprovado","Reprovado")) -> Aprovado
A34: 11 | B34: 0.416 | C34: =IF(B34="","",IF(B34<=$D$20,IF(B34>=$C$20,"Aprovado","Reprovado"),"Reprovado")) -> Aprovado | D34: 0.255 | E34: =IF(D34="","",IF(D34>=$E$20,"Aprovado","Reprovado")) -> Aprovado
A35: 12 | B35: 0.414 | C35: =IF(B35="","",IF(B35<=$D$20,IF(B35>=$C$20,"Aprovado","Reprovado"),"Reprovado")) -> Aprovado | D35: 0.252 | E35: =IF(D35="","",IF(D35>=$E$20,"Aprovado","Reprovado")) -> Aprovado
... A55: 32 | B55: 0.416 | C55: =IF(B55="","",IF(B55<=$D$20,IF(B55>=$C$20,"Aprovado","Reprovado"),"Reprovado")) -> Aprovado | D55: 0.25 | E55: =IF(D55="","",IF(D55>=$E$20,"Aprovado","Reprovado")) -> Aprovado
E56: =IF(D56="","",IF(D56>=$E$20,"Aprovado","Reprovado"))
E57: =IF(D57="","",IF(D57>=$E$20,"Aprovado","Reprovado"))
B58: Conferido por: João J. da Silva.
B61: Anexo 2 - MS- 0028921_Rev.04 - Dimensões - (Diâmetro Externo e Interno).

Sheet MS-0028921 Rigidez ISO9626
C2: Formulário de Registro para Rigidez da cânula -9626 Agulha
B5: Ordem de Serviço - OS | C5: BR26NODK 001
B6: Técnico responsável: | C6: João / Raissa
B7: Norma e Item da norma: | C7: ABNT NBR ISO 9626:2020 - Item 5.8 Rigidez (Item 4.10.1 da 7864:2020)
B8: Fabricante: | C8: Terumo Europe - Bélgica.
B9: Produto: | C9: ='MS- 0028921 Limpeza'!C9 -> Agulha hipodérmica estéril para uso único
B10: Modelo: | C10: Agulha Hipodérmica LL e LS (K-Pack) 0,40 x 12 mm 27G X 1/2 - Cod: KH-2713RBBTUCI - Lote: 2509064, (TÜV 25.1393)
B11: Observações:
B12: Informações adicionais do ensaio
B13: Equipamentos utilizados: | C13: Dispositivo de Rigidez TUV-LAB-0970, Termohigrômetro TUV-LAB-1116, Paquimetro TUV-LAB-1146.
B14: Data de execução do ensaio: | C14: 1703/2026
B15: Condições Ambientais | C15: Temperatura (°C): 24 | D15: Umidade (%): 67
B17: Diâmetro externo da cânula (mm) | C17: Tipo de parede | D17: Vão Ajustável (mm) | E17: Força de Dobramento (N) | F17: Deflexão Máxima (mm)
B18: 0.4 | C18: Fina | D18: 7.5 | E18: 3.4 | F18: 0.34
B20: Força Aplicada (N) | C20: Deflexão Medida (mm) | D20: Fator de correção da Deflexão | E20: Valor corrigido | F20: Verificação
A21: 1 | B21: =E18 -> 3.4 | C21: 0.22 | D21: 0.06 | E21: =IF(D21="","",C21-D21) -> 0.16 | F21: =IF(E21="","",IF(E21<=$F$18,"Aprovado","Reprovado")) -> Aprovado
A22: 2 | B22: =E18 -> 3.4 | C22: 0.19 | D22: 0.06 | E22: =IF(D22="","",C22-D22) -> 0.13 | F22: =IF(E22="","",IF(E22<=$F$18,"Aprovado","Reprovado")) -> Aprovado
A23: 3 | B23: =E18 -> 3.4 | C23: 0.22 | D23: 0.06 | E23: =IF(D23="","",C23-D23) -> 0.16 | F23: =IF(E23="","",IF(E23<=$F$18,"Aprovado","Reprovado")) -> Aprovado
A24: 4 | B24: =E18 -> 3.4 | C24: 0.18 | D24: 0.06 | E24: =IF(D24="","",C24-D24) -> 0.12 | F24: =IF(E24="","",IF(E24<=$F$18,"Aprovado","Reprovado")) -> Aprovado
A25: 5 | B25: =E18 -> 3.4 | C25: 0.18 | D25: 0.06 | E25: =IF(D25="","",C25-D25) -> 0.12 | F25: =IF(E25="","",IF(E25<=$F$18,"Aprovado","Reprovado")) -> Aprovado
A26: 6 | B26: =E18 -> 3.4 | C26: 0.21 | D26: 0.06 | E26: =IF(D26="","",C26-D26) -> 0.15 | F26: =IF(E26="","",IF(E26<=$F$18,"Aprovado","Reprovado")) -> Aprovado
A27: 7 | B27: =E18 -> 3.4 | C27: 0.21 | D27: 0.06 | E27: =IF(D27="","",C27-D27) -> 0.15 | F27: =IF(E27="","",IF(E27<=$F$18,"Aprovado","Reprovado")) -> Aprovado
A28: 8 | B28: =E18 -> 3.4 | C28: 0.18 | D28: 0.06 | E28: =IF(D28="","",C28-D28) -> 0.12 | F28: =IF(E28="","",IF(E28<=$F$18,"Aprovado","Reprovado")) -> Aprovado
A29: 9 | B29: =E18 -> 3.4 | C29: 0.21 | D29: 0.06 | E29: =IF(D29="","",C29-D29) -> 0.15 | F29: =IF(E29="","",IF(E29<=$F$18,"Aprovado","Reprovado")) -> Aprovado
A30: 10 | B30: =E18 -> 3.4 | C30: 0.17 | D30: 0.06 | E30: =IF(D30="","",C30-D30) -> 0.11 | F30: =IF(E30="","",IF(E30<=$F$18,"Aprovado","Reprovado")) -> Aprovado
A31: 11 | B31: =E18 -> 3.4 | C31: 0.2 | D31: 0.06 | E31: =IF(D31="","",C31-D31) -> 0.14 | F31: =IF(E31="","",IF(E31<=$F$18,"Aprovado","Reprovado")) -> Aprovado
A32: 12 | B32: =E18 -> 3.4 | C32: 0.21 | D32: 0.06 | E32: =IF(D32="","",C32-D32) -> 0.15 | F32: =IF(E32="","",IF(E32<=$F$18,"Aprovado","Reprovado")) -> Aprovado
A33: 13 | B33: =E18 -> 3.4 | C33: 0.19 | D33: 0.06 | E33: =IF(D33="","",C33-D33) -> 0.13 | F33: =IF(E33="","",IF(E33<=$F$18,"Aprovado","Reprovado")) -> Aprovado
A34: 14 | B34: =E18 -> 3.4 | C34: 0.2 | D34: 0.06 | E34: =IF(D34="","",C34-D34) -> 0.14 | F34: =IF(E34="","",IF(E34<=$F$18,"Aprovado","Reprovado")) -> Aprovado
A35: 15 | B35: =E18 -> 3.4 | C35: 0.22 | D35: 0.06 | E35: =IF(D35="","",C35-D35) -> 0.16 | F35: =IF(E35="","",IF(E35<=$F$18,"Aprovado","Reprovado")) -> Aprovado
A36: 16 | B36: =E18 -> 3.4 | C36: 0.2 | D36: 0.06 | E36: =IF(D36="","",C36-D36) -> 0.14 | F36: =IF(E36="","",IF(E36<=$F$18,"Aprovado","Reprovado")) -> Aprovado
A37: 17 | B37: =E18 -> 3.4 | C37: 0.2 | D37: 0.06 | E37: =IF(D37="","",C37-D37) -> 0.14 | F37: =IF(E37="","",IF(E37<=$F$18,"Aprovado","Reprovado")) -> Aprovado
A38: 18 | B38: =E18 -> 3.4 | C38: 0.22 | D38: 0.06 | E38: =IF(D38="","",C38-D38) -> 0.16 | F38: =IF(E38="","",IF(E38<=$F$18,"Aprovado","Reprovado")) -> Aprovado
A39: 19 | B39: =E18 -> 3.4 | C39: 0.21 | D39: 0.06 | E39: =IF(D39="","",C39-D39) -> 0.15 | F39: =IF(E39="","",IF(E39<=$F$18,"Aprovado","Reprovado")) -> Aprovado
A40: 20 | B40: =E18 -> 3.4 | C40: 0.21 | D40: 0.06 | E40: =IF(D40="","",C40-D40) -> 0.15 | F40: =IF(E40="","",IF(E40<=$F$18,"Aprovado","Reprovado")) -> Aprovado
A41: 21 | B41: =E18 -> 3.4 | C41: 0.22 | D41: 0.06 | E41: =IF(D41="","",C41-D41) -> 0.16 | F41: =IF(E41="","",IF(E41<=$F$18,"Aprovado","Reprovado")) -> Aprovado
A42: 22 | B42: =E18 -> 3.4 | C42: 0.21 | D42: 0.06 | E42: =IF(D42="","",C42-D42) -> 0.15 | F42: =IF(E42="","",IF(E42<=$F$18,"Aprovado","Reprovado")) -> Aprovado
A43: 23 | B43: =E18 -> 3.4 | C43: 0.22 | D43: 0.06 | E43: =IF(D43="","",C43-D43) -> 0.16 | F43: =IF(E43="","",IF(E43<=$F$18,"Aprovado","Reprovado")) -> Aprovado
A44: 24 | B44: =E18 -> 3.4 | C44: 0.21 | D44: 0.06 | E44: =IF(D44="","",C44-D44) -> 0.15 | F44: =IF(E44="","",IF(E44<=$F$18,"Aprovado","Reprovado")) -> Aprovado
A45: 25 | B45: =E18 -> 3.4 | C45: 0.2 | D45: 0.06 | E45: =IF(D45="","",C45-D45) -> 0.14 | F45: =IF(E45="","",IF(E45<=$F$18,"Aprovado","Reprovado")) -> Aprovado
...

Sheet MS-0028921 Resistência quebra
C2: Formulário de Registro para Resistência à quebra - Agulhas
B5: Ordem de Serviço - OS | C5: BR26NODK 001
B6: Técnico responsável: | C6: João / Raissa
B7: Norma e Item da norma: | C7: ABNT NBR ISO 9626:2020 - Item 5.9 Resistência à quebra (Item 4.10.1 da 7864:2020)
B8: Fabricante: | C8: Terumo Europe - Bélgica.
B9: Produto: | C9: ='MS- 0028921 Limpeza'!C9 -> Agulha hipodérmica estéril para uso único
B10: Modelo: | C10: Agulha Hipodérmica LL e LS (K-Pack) 0,40 x 12 mm 27G X 1/2 - Cod: KH-2713RBBTUCI - Lote: 2509064, (TÜV 25.1393)
B11: Observações:
B12: Informações adicionais do ensaio
B13: Equipamentos utilizados: | C13: Paquimetro TUV-LAB-1147, Termohigrômetro TUV-LAB-1116, Dispositivo de R.Quebra TUV-LAB-0938.
B14: Data de execução do ensaio: | C14: 46091
B15: Condições Ambientais | C15: Temperatura (°C): 22 | D15: Umidade (%): 71
B18: Distância do vão (mm) | C18: Tipo de parede | D18: Ângulo aplicado
B19: 8 | C19: fina
B21: Atende ao requisito ? | C21: Observações
A22: 1
A23: 2
A24: 3
A25: 4
A26: 5
A27: 6
A28: 7
A29: 8
A30: 9
A31: 10
A32: 11
A33: 12
... A53: 32
B55: Conferido por: João J. da Silva.

Sheet MS-0028921 Resist. Corrosão
C2: Formulário de Registro de Resistência à Corrosão - Cânula
B5: Ordem de Serviço - OS | C5: BR26NODK 001
B6: Técnico responsável: | C6: João / Raissa
B7: Norma e Item da norma: | C7: ABNT NBR ISO 9626:2020 - Item 5.10 Resistência à corrosão (Item 4.10.1 da 7864:2020)
B8: Fabricante: | C8: Terumo Europe - Bélgica.
B9: Produto: | C9: ='MS- 0028921 Limpeza'!C9 -> Agulha hipodérmica estéril para uso único
B10: Modelo: | C10: Agulha Hipodérmica LL e LS (K-Pack) 0,40 x 12 mm 27G X 1/2 - Cod: KH-2713RBBTUCI - Lote: 2509064, (TÜV 25.1393)
B11: Observações:
B12: Informações adicionais do ensaio
B13: Equipamentos utilizados: | C13: Cronômetro 9018144, Termohigrômetro TUV-LAB-1520.
B14: Data de execução do ensaio: | C14: 46080
B15: Condições Ambientais | C15: Temperatura (°C): 22 | D15: Umidade (%): 74
B16: Tempo de ensaio | C16: Início: 8h | D16: Término: 15h
B17: Produtos químicos | D17: Números: 776
B19: Apresenta sinais de corrosão? | C19: Observações
A20: 1
A21: 2
A22: 3
A23: 4
A24: 5
A25: 6
A26: 7
A27: 8
A28: 9
A29: 10
A30: 11
A31: 12
... A51: 32
B53: Conferido por: João J. da Silva.

Sheet MS-0028921 Toler. ISO 7864
C2: Formulário de Registro para Tolerância do comprimento da cânula - Agulha
B5: Ordem de Serviço - OS | C5: BR26NODK 001
B6: Técnico responsável: | C6: João / Raissa
B7: Norma e Item da norma: | C7: ABNT NBR ISO 7864:2020 - Item 4.10.2 Tolerância do comprimento.
B8: Fabricante: | C8: Terumo Europe - Bélgica.
B9: Produto: | C9: ='MS- 0028921 Limpeza'!C9 -> Agulha hipodérmica estéril para uso único
B10: Modelo: | C10: Agulha Hipodérmica LL e LS (K-Pack) 0,40 x 12 mm 27G X 1/2 - Cod: KH-2713RBBTUCI - Lote: 2509064, (TÜV 25.1393)
B11: Observações:
B12: Informações adicionais do ensaio
B13: Equipamentos utilizados: | C13: Paquímetro TUV-LAB-1147, Termohigrômetro 9058343.
B14: Data de execução do ensaio: | C14: 46085
B15: Condições Ambientais | C15: Temperatura (°C): 22 | D15: Umidade (%): 59
B19: Comprimento da cânula (mm) | C19: Tolerância Valor Máximo Especificado (mm) | D19: Tolerância Valor Mínimo Especificado (mm)
B21: 12 | C21: 1 | D21: 2
C22: =IF(B21="","",(B21+C21)) -> 13 | D22: =IF(B21="","",B21-D21) -> 10
B25: Comprimento Medido (mm) | C25: Verificação
A26: 1 | B26: 12.09 | C26: =IF(B26="","",IF(B26>=$D$22,IF(B26<=$C$22,"Aprovado","Reprovado"),"Reprovado")) -> Aprovado
A27: 2 | B27: 11.92 | C27: =IF(B27="","",IF(B27>=$D$22,IF(B27<=$C$22,"Aprovado","Reprovado"),"Reprovado")) -> Aprovado
A28: 3 | B28: 11.68 | C28: =IF(B28="","",IF(B28>=$D$22,IF(B28<=$C$22,"Aprovado","Reprovado"),"Reprovado")) -> Aprovado
A29: 4 | B29: 11.6 | C29: =IF(B29="","",IF(B29>=$D$22,IF(B29<=$C$22,"Aprovado","Reprovado"),"Reprovado")) -> Aprovado
A30: 5 | B30: 12.19 | C30: =IF(B30="","",IF(B30>=$D$22,IF(B30<=$C$22,"Aprovado","Reprovado"),"Reprovado")) -> Aprovado
A31: 6 | B31: 11.97 | C31: =IF(B31="","",IF(B31>=$D$22,IF(B31<=$C$22,"Aprovado","Reprovado"),"Reprovado")) -> Aprovado
A32: 7 | B32: 11.83 | C32: =IF(B32="","",IF(B32>=$D$22,IF(B32<=$C$22,"Aprovado","Reprovado"),"Reprovado")) -> Aprovado
A33: 8 | B33: 11.5 | C33: =IF(B33="","",IF(B33>=$D$22,IF(B33<=$C$22,"Aprovado","Reprovado"),"Reprovado")) -> Aprovado
A34: 9 | B34: 11.92 | C34: =IF(B34="","",IF(B34>=$D$22,IF(B34<=$C$22,"Aprovado","Reprovado"),"Reprovado")) -> Aprovado
A35: 10 | B35: 11.98 | C35: =IF(B35="","",IF(B35>=$D$22,IF(B35<=$C$22,"Aprovado","Reprovado"),"Reprovado")) -> Aprovado
A36: 11 | B36: 11.97 | C36: =IF(B36="","",IF(B36>=$D$22,IF(B36<=$C$22,"Aprovado","Reprovado"),"Reprovado")) -> Aprovado
A37: 12 | B37: 11.83 | C37: =IF(B37="","",IF(B37>=$D$22,IF(B37<=$C$22,"Aprovado","Reprovado"),"Reprovado")) -> Aprovado
... A57: 32 | B57: 11.7 | C57: =IF(B57="","",IF(B57>=$D$22,IF(B57<=$C$22,"Aprovado","Reprovado"),"Reprovado")) -> Aprovado
B59: Conferido por: João J. da Silva.

Sheet MS-0028921 Canhão e cânula 
C2: Formulário de Registro para União entre o canhão e a cânula - Agulha
B5: Ordem de Serviço - OS | C5: BR26NODK 001
B6: Técnico responsável: | C6: João / Raissa
B7: Norma e Item da norma: | C7: ABNT NBR ISO 7864:2020 - 4.12 União entre o canhão e a cânula
B8: Fabricante: | C8: Terumo Europe - Bélgica.
B9: Produto: | C9: ='MS- 0028921 Limpeza'!C9 -> Agulha hipodérmica estéril para uso único
B10: Modelo: | C10: Agulha Hipodérmica LL e LS (K-Pack) 0,40 x 12 mm 27G X 1/2 - Cod: KH-2713RBBTUCI - Lote: 2509064, (TÜV 25.1393)
B11: Observações:
B12: Informações adicionais do ensaio
B13: Equipamentos utilizados: | C13: Dispositivo de tração e compressão TUV-LAB-0917, Termohigrômetro TUV-LAB-1116.
B14: Data de execução do ensaio: | C14: 46087
B15: Condições Ambientais | C15: Temperatura (°C): 23 | D15: Umidade (%): 70
B17: Diâmetro externo nominal da agulha (mm) | C17: Força mínima permitida (N)
B18: 0,40 x 12 | C18: 22
B21: Força de ruptura medida (N) | C21: Verificação
A22: 1 | B22: 50 | C22: =IF(B22="","",IF(B22>=$C$18,"Aprovado","Reprovado")) -> Aprovado
A23: 2 | B23: 51 | C23: =IF(B23="","",IF(B23>=$C$18,"Aprovado","Reprovado")) -> Aprovado
A24: 3 | B24: 70 | C24: =IF(B24="","",IF(B24>=$C$18,"Aprovado","Reprovado")) -> Aprovado
A25: 4 | B25: 65 | C25: =IF(B25="","",IF(B25>=$C$18,"Aprovado","Reprovado")) -> Aprovado
A26: 5 | B26: 61 | C26: =IF(B26="","",IF(B26>=$C$18,"Aprovado","Reprovado")) -> Aprovado
A27: 6 | B27: 62 | C27: =IF(B27="","",IF(B27>=$C$18,"Aprovado","Reprovado")) -> Aprovado
A28: 7 | B28: 49 | C28: =IF(B28="","",IF(B28>=$C$18,"Aprovado","Reprovado")) -> Aprovado
A29: 8 | B29: 56 | C29: =IF(B29="","",IF(B29>=$C$18,"Aprovado","Reprovado")) -> Aprovado
A30: 9 | B30: 69 | C30: =IF(B30="","",IF(B30>=$C$18,"Aprovado","Reprovado")) -> Aprovado
A31: 10 | B31: 62 | C31: =IF(B31="","",IF(B31>=$C$18,"Aprovado","Reprovado")) -> Aprovado
A32: 11 | B32: 47 | C32: =IF(B32="","",IF(B32>=$C$18,"Aprovado","Reprovado")) -> Aprovado
A33: 12 | B33: 60 | C33: =IF(B33="","",IF(B33>=$C$18,"Aprovado","Reprovado")) -> Aprovado
... A53: 32 | B53: 63 | C53: =IF(B53="","",IF(B53>=$C$18,"Aprovado","Reprovado")) -> Aprovado
B55: Conferido por: João J. da Silva.

Sheet MS-0028921 Diâmetro Interno
C2: Formulário de Registro para Tolerância do Diâmetro interno do tubo da Cânula da Agulha
B5: Ordem de Serviço - OS | C5: BR26NODK 001
B6: Técnico responsável: | C6: João / Raissa
B7: Norma e Item da norma: | C7: ABNT NBR ISO 7864:2020 - 4.13 Diâmetro interno
B8: Fabricante: | C8: Terumo Europe - Bélgica.
B9: Produto: | C9: ='MS- 0028921 Limpeza'!C9 -> Agulha hipodérmica estéril para uso único
B10: Modelo: | C10: Agulha Hipodérmica LL e LS (K-Pack) 0,40 x 12 mm 27G X 1/2 - Cod: KH-2713RBBTUCI - Lote: 2509064, (TÜV 25.1393)
B11: Observações:
B12: Informações adicionais do ensaio
B13: Equipamentos utilizados: | C13: Conjunto de pinos padrões TUV-LAB-0948 , Termohigrometro 9058343.
B14: Data de execução do ensaio: | C14: 46090
B15: Condições Ambientais | C15: Temperatura (°C): 22 | D15: Umidade (%): 64
B16: Verificação do diâmetro do pino, antes do uso (mm) | C16: 0.191
B17: Equipamento utilizado na verificação: | C17: Micômetro TUV-LAB-0902
B20: Diâmetro Externo Nominal (mm) | C20: Diâmetro do pino (mm) | D20: Tipo de parede
B21: 0.4 | C21: 0.19 | D21: Fina
B24: Passou pelo pino ?
A25: 1
A26: 2
A27: 3
A28: 4
A29: 5
A30: 6
A31: 7
A32: 8
A33: 9
A34: 10
A35: 11
A36: 12
... A56: 32
B58: Conferido por: João J. da Silva.

Sheet MS- 0028921 ISO 594-1 e 594-2
D2: Formulário de Registro para ISO 594-1
C6: Ordem de Serviço - OS
C7: Técnico responsável:
C8: Norma e Item da norma: | D8: ABNT NBR ISO 594-1:2003 - Requisitos gerais
C9: Fabricante:
C10: Produto: | D10: Agulha hipodérmica estéril para uso único
C11: Modelo:
C12: Observações:
C13: Informações adicionais de ensaio
C14: Equipamentos utilizados: | D14: Dinamômetro TUV-LAB-1112, Termohigrômetro TUV-LAB-1116, Calibre TUV-LAB-1135-2, Calibre TUV-LAB-1135-5 e Calibres Ruptura 9015825, Manômetro TUV-LAB-1471, Cronômetro 9018144, Termohigrômetro TUV-LAB-1520, Peso padrão UC-MEL-635, Disp de apoio TUV-LAB 0988, Disp de apoio TUV-LAB 1469.
C16: Data de execução do ensaio:
C17: Condições Ambientais | D17: Temperatura (°C): | F17: Umidade (%):
C19: ABNT NBR ISO 594-1
C20: 4.1 - Calibração Atende ao requisito? | D20: 4.2 Vazamento de Liquidos Atende ao requisito? | E20: 4.3 Vazamento de ar Atende ao requisito? | F20: 4.4 Força de Separação Atende ao requisito? | G20: 4.5 - Esforço de Ruptura Atende ao requisito? | H20: Observação
B21: 1
B22: 2
B23: 3
B24: 4
B25: 5
B26: 6
B27: 7
B28: 8
B29: 9
B30: 10
B31: 11
B32: 12
... B52: 32
C54: Conferido por: João J. da Silva.
D57: Formulário de Registro para ISO 594-2
C61: Ordem de Serviço - OS
C62: Técnico responsável:
C63: Norma e Item da norma: | D63: ABNT NBR ISO 594-2:2003 - Montagem Fixa
C64: Fabricante:
C65: Produto: | D65: Agulha hipodérmica estéril para uso único
C66: Modelo:
C67: Observações:
C68: Informações adicionais de ensaio
C69: Equipamentos utilizados: | D69: Dinamometro , Termohigrometro, Calibre , Calibre e Calibres , Manometro , Cronometro , Termohigromêtro , Peso padrão , Disp de apoio , Disp de apoio .
C71: Data de execução do ensaio:
C72: Condições Ambientais | D72: Temperatura (°C): | F72: Umidade (%):
...
